[2023-07-18T19:01:29.351+0000] {taskinstance.py:1103} INFO - Dependencies all met for dep_context=non-requeueable deps ti=<TaskInstance: etl_uber_data.load_postgres manual__2023-07-18T19:01:23.465650+00:00 [queued]>
[2023-07-18T19:01:29.359+0000] {taskinstance.py:1103} INFO - Dependencies all met for dep_context=requeueable deps ti=<TaskInstance: etl_uber_data.load_postgres manual__2023-07-18T19:01:23.465650+00:00 [queued]>
[2023-07-18T19:01:29.360+0000] {taskinstance.py:1308} INFO - Starting attempt 1 of 2
[2023-07-18T19:01:29.371+0000] {taskinstance.py:1327} INFO - Executing <Task(PythonOperator): load_postgres> on 2023-07-18 19:01:23.465650+00:00
[2023-07-18T19:01:29.376+0000] {standard_task_runner.py:57} INFO - Started process 2434 to run task
[2023-07-18T19:01:29.378+0000] {standard_task_runner.py:84} INFO - Running: ['***', 'tasks', 'run', 'etl_uber_data', 'load_postgres', 'manual__2023-07-18T19:01:23.465650+00:00', '--job-id', '490', '--raw', '--subdir', 'DAGS_FOLDER/etl_uber_data.py', '--cfg-path', '/tmp/tmpvije4nyp']
[2023-07-18T19:01:29.380+0000] {standard_task_runner.py:85} INFO - Job 490: Subtask load_postgres
[2023-07-18T19:01:29.417+0000] {task_command.py:410} INFO - Running <TaskInstance: etl_uber_data.load_postgres manual__2023-07-18T19:01:23.465650+00:00 [running]> on host 4488070fba17
[2023-07-18T19:01:29.484+0000] {taskinstance.py:1547} INFO - Exporting env vars: AIRFLOW_CTX_DAG_OWNER='Mervyn Frost' AIRFLOW_CTX_DAG_ID='etl_uber_data' AIRFLOW_CTX_TASK_ID='load_postgres' AIRFLOW_CTX_EXECUTION_DATE='2023-07-18T19:01:23.465650+00:00' AIRFLOW_CTX_TRY_NUMBER='1' AIRFLOW_CTX_DAG_RUN_ID='manual__2023-07-18T19:01:23.465650+00:00'
[2023-07-18T19:01:29.805+0000] {taskinstance.py:1824} ERROR - Task failed with exception
Traceback (most recent call last):
  File "/home/airflow/.local/lib/python3.7/site-packages/airflow/operators/python.py", line 181, in execute
    return_value = self.execute_callable()
  File "/home/airflow/.local/lib/python3.7/site-packages/airflow/operators/python.py", line 198, in execute_callable
    return self.python_callable(*self.op_args, **self.op_kwargs)
  File "/opt/airflow/dags/etl_uber_data.py", line 137, in load
    datetime_dim.to_sql('datetime_dim', engine)
  File "/home/airflow/.local/lib/python3.7/site-packages/pandas/core/generic.py", line 2882, in to_sql
    method=method,
  File "/home/airflow/.local/lib/python3.7/site-packages/pandas/io/sql.py", line 728, in to_sql
    **engine_kwargs,
  File "/home/airflow/.local/lib/python3.7/site-packages/pandas/io/sql.py", line 1758, in to_sql
    dtype=dtype,
  File "/home/airflow/.local/lib/python3.7/site-packages/pandas/io/sql.py", line 1650, in prep_table
    table.create()
  File "/home/airflow/.local/lib/python3.7/site-packages/pandas/io/sql.py", line 858, in create
    raise ValueError(f"Table '{self.name}' already exists.")
ValueError: Table 'datetime_dim' already exists.
[2023-07-18T19:01:29.822+0000] {taskinstance.py:1350} INFO - Marking task as UP_FOR_RETRY. dag_id=etl_uber_data, task_id=load_postgres, execution_date=20230718T190123, start_date=20230718T190129, end_date=20230718T190129
[2023-07-18T19:01:29.835+0000] {standard_task_runner.py:109} ERROR - Failed to execute job 490 for task load_postgres (Table 'datetime_dim' already exists.; 2434)
[2023-07-18T19:01:29.872+0000] {local_task_job_runner.py:225} INFO - Task exited with return code 1
[2023-07-18T19:01:29.886+0000] {taskinstance.py:2653} INFO - 0 downstream tasks scheduled from follow-on schedule check
