[2023-07-18T19:04:28.311+0000] {taskinstance.py:1103} INFO - Dependencies all met for dep_context=non-requeueable deps ti=<TaskInstance: etl_uber_data.load_postgres manual__2023-07-18T19:01:23.465650+00:00 [queued]>
[2023-07-18T19:04:28.318+0000] {taskinstance.py:1103} INFO - Dependencies all met for dep_context=requeueable deps ti=<TaskInstance: etl_uber_data.load_postgres manual__2023-07-18T19:01:23.465650+00:00 [queued]>
[2023-07-18T19:04:28.319+0000] {taskinstance.py:1308} INFO - Starting attempt 3 of 4
[2023-07-18T19:04:28.330+0000] {taskinstance.py:1327} INFO - Executing <Task(PythonOperator): load_postgres> on 2023-07-18 19:01:23.465650+00:00
[2023-07-18T19:04:28.336+0000] {standard_task_runner.py:57} INFO - Started process 2777 to run task
[2023-07-18T19:04:28.338+0000] {standard_task_runner.py:84} INFO - Running: ['***', 'tasks', 'run', 'etl_uber_data', 'load_postgres', 'manual__2023-07-18T19:01:23.465650+00:00', '--job-id', '496', '--raw', '--subdir', 'DAGS_FOLDER/etl_uber_data.py', '--cfg-path', '/tmp/tmpi6t9vjv5']
[2023-07-18T19:04:28.340+0000] {standard_task_runner.py:85} INFO - Job 496: Subtask load_postgres
[2023-07-18T19:04:28.376+0000] {task_command.py:410} INFO - Running <TaskInstance: etl_uber_data.load_postgres manual__2023-07-18T19:01:23.465650+00:00 [running]> on host 4488070fba17
[2023-07-18T19:04:28.444+0000] {taskinstance.py:1547} INFO - Exporting env vars: AIRFLOW_CTX_DAG_OWNER='Mervyn Frost' AIRFLOW_CTX_DAG_ID='etl_uber_data' AIRFLOW_CTX_TASK_ID='load_postgres' AIRFLOW_CTX_EXECUTION_DATE='2023-07-18T19:01:23.465650+00:00' AIRFLOW_CTX_TRY_NUMBER='3' AIRFLOW_CTX_DAG_RUN_ID='manual__2023-07-18T19:01:23.465650+00:00'
[2023-07-18T19:04:49.144+0000] {taskinstance.py:1824} ERROR - Task failed with exception
Traceback (most recent call last):
  File "/home/airflow/.local/lib/python3.7/site-packages/airflow/operators/python.py", line 181, in execute
    return_value = self.execute_callable()
  File "/home/airflow/.local/lib/python3.7/site-packages/airflow/operators/python.py", line 198, in execute_callable
    return self.python_callable(*self.op_args, **self.op_kwargs)
  File "/opt/airflow/dags/etl_uber_data.py", line 157, in load
    cursor.execute(sql)
psycopg2.errors.UndefinedTable: relation "modeling_uber_data.pg_tables" does not exist
LINE 1: SELECT * FROM modeling_uber_data.pg_tables;
                      ^

[2023-07-18T19:04:49.155+0000] {taskinstance.py:1350} INFO - Marking task as UP_FOR_RETRY. dag_id=etl_uber_data, task_id=load_postgres, execution_date=20230718T190123, start_date=20230718T190428, end_date=20230718T190449
[2023-07-18T19:04:49.165+0000] {standard_task_runner.py:109} ERROR - Failed to execute job 496 for task load_postgres (relation "modeling_uber_data.pg_tables" does not exist
LINE 1: SELECT * FROM modeling_uber_data.pg_tables;
                      ^
; 2777)
[2023-07-18T19:04:49.181+0000] {local_task_job_runner.py:225} INFO - Task exited with return code 1
[2023-07-18T19:04:49.193+0000] {taskinstance.py:2653} INFO - 0 downstream tasks scheduled from follow-on schedule check
