[2023-07-10T09:16:48.107+0000] {taskinstance.py:1103} INFO - Dependencies all met for dep_context=non-requeueable deps ti=<TaskInstance: etl_uber_data.load_postgres manual__2023-07-10T02:44:19.817965+00:00 [queued]>
[2023-07-10T09:16:48.117+0000] {taskinstance.py:1103} INFO - Dependencies all met for dep_context=requeueable deps ti=<TaskInstance: etl_uber_data.load_postgres manual__2023-07-10T02:44:19.817965+00:00 [queued]>
[2023-07-10T09:16:48.117+0000] {taskinstance.py:1308} INFO - Starting attempt 28 of 29
[2023-07-10T09:16:48.129+0000] {taskinstance.py:1327} INFO - Executing <Task(PythonOperator): load_postgres> on 2023-07-10 02:44:19.817965+00:00
[2023-07-10T09:16:48.134+0000] {standard_task_runner.py:57} INFO - Started process 29650 to run task
[2023-07-10T09:16:48.136+0000] {standard_task_runner.py:84} INFO - Running: ['***', 'tasks', 'run', 'etl_uber_data', 'load_postgres', 'manual__2023-07-10T02:44:19.817965+00:00', '--job-id', '386', '--raw', '--subdir', 'DAGS_FOLDER/etl_uber_data.py', '--cfg-path', '/tmp/tmpyaf1c8u7']
[2023-07-10T09:16:48.137+0000] {standard_task_runner.py:85} INFO - Job 386: Subtask load_postgres
[2023-07-10T09:16:48.176+0000] {task_command.py:410} INFO - Running <TaskInstance: etl_uber_data.load_postgres manual__2023-07-10T02:44:19.817965+00:00 [running]> on host 1481ab9bb806
[2023-07-10T09:16:48.240+0000] {taskinstance.py:1547} INFO - Exporting env vars: AIRFLOW_CTX_DAG_OWNER='Mervyn Frost' AIRFLOW_CTX_DAG_ID='etl_uber_data' AIRFLOW_CTX_TASK_ID='load_postgres' AIRFLOW_CTX_EXECUTION_DATE='2023-07-10T02:44:19.817965+00:00' AIRFLOW_CTX_TRY_NUMBER='28' AIRFLOW_CTX_DAG_RUN_ID='manual__2023-07-10T02:44:19.817965+00:00'
[2023-07-10T09:16:48.285+0000] {taskinstance.py:1824} ERROR - Task failed with exception
Traceback (most recent call last):
  File "/home/airflow/.local/lib/python3.7/site-packages/airflow/operators/python.py", line 181, in execute
    return_value = self.execute_callable()
  File "/home/airflow/.local/lib/python3.7/site-packages/airflow/operators/python.py", line 198, in execute_callable
    return self.python_callable(*self.op_args, **self.op_kwargs)
  File "/opt/airflow/dags/etl_uber_data.py", line 172, in load
    datetime_dim.to_sql('datetime_dim', engine)
AttributeError: 'NoneType' object has no attribute 'to_sql'
[2023-07-10T09:16:48.296+0000] {taskinstance.py:1350} INFO - Marking task as UP_FOR_RETRY. dag_id=etl_uber_data, task_id=load_postgres, execution_date=20230710T024419, start_date=20230710T091648, end_date=20230710T091648
[2023-07-10T09:16:48.305+0000] {standard_task_runner.py:109} ERROR - Failed to execute job 386 for task load_postgres ('NoneType' object has no attribute 'to_sql'; 29650)
[2023-07-10T09:16:48.349+0000] {local_task_job_runner.py:225} INFO - Task exited with return code 1
[2023-07-10T09:16:48.371+0000] {taskinstance.py:2653} INFO - 0 downstream tasks scheduled from follow-on schedule check
