[2023-07-10T04:11:35.645+0000] {taskinstance.py:1103} INFO - Dependencies all met for dep_context=non-requeueable deps ti=<TaskInstance: etl_uber_data.load_postgres manual__2023-07-10T02:44:19.817965+00:00 [queued]>
[2023-07-10T04:11:35.652+0000] {taskinstance.py:1103} INFO - Dependencies all met for dep_context=requeueable deps ti=<TaskInstance: etl_uber_data.load_postgres manual__2023-07-10T02:44:19.817965+00:00 [queued]>
[2023-07-10T04:11:35.653+0000] {taskinstance.py:1308} INFO - Starting attempt 4 of 5
[2023-07-10T04:11:35.665+0000] {taskinstance.py:1327} INFO - Executing <Task(PythonOperator): load_postgres> on 2023-07-10 02:44:19.817965+00:00
[2023-07-10T04:11:35.669+0000] {standard_task_runner.py:57} INFO - Started process 5701 to run task
[2023-07-10T04:11:35.671+0000] {standard_task_runner.py:84} INFO - Running: ['***', 'tasks', 'run', 'etl_uber_data', 'load_postgres', 'manual__2023-07-10T02:44:19.817965+00:00', '--job-id', '45', '--raw', '--subdir', 'DAGS_FOLDER/etl_uber_data.py', '--cfg-path', '/tmp/tmpjbx82wa2']
[2023-07-10T04:11:35.673+0000] {standard_task_runner.py:85} INFO - Job 45: Subtask load_postgres
[2023-07-10T04:11:35.713+0000] {task_command.py:410} INFO - Running <TaskInstance: etl_uber_data.load_postgres manual__2023-07-10T02:44:19.817965+00:00 [running]> on host 1481ab9bb806
[2023-07-10T04:11:35.774+0000] {taskinstance.py:1547} INFO - Exporting env vars: AIRFLOW_CTX_DAG_OWNER='Mervyn Frost' AIRFLOW_CTX_DAG_ID='etl_uber_data' AIRFLOW_CTX_TASK_ID='load_postgres' AIRFLOW_CTX_EXECUTION_DATE='2023-07-10T02:44:19.817965+00:00' AIRFLOW_CTX_TRY_NUMBER='4' AIRFLOW_CTX_DAG_RUN_ID='manual__2023-07-10T02:44:19.817965+00:00'
[2023-07-10T04:11:37.388+0000] {taskinstance.py:1824} ERROR - Task failed with exception
Traceback (most recent call last):
  File "/home/airflow/.local/lib/python3.7/site-packages/airflow/operators/python.py", line 181, in execute
    return_value = self.execute_callable()
  File "/home/airflow/.local/lib/python3.7/site-packages/airflow/operators/python.py", line 198, in execute_callable
    return self.python_callable(*self.op_args, **self.op_kwargs)
  File "/opt/airflow/dags/etl_uber_data.py", line 121, in load
    engine = create_engine('postgres://airflow:airflow@localhost:5432/modeling_uber_data')
  File "<string>", line 2, in create_engine
  File "/home/airflow/.local/lib/python3.7/site-packages/sqlalchemy/util/deprecations.py", line 375, in warned
    return fn(*args, **kwargs)
  File "/home/airflow/.local/lib/python3.7/site-packages/sqlalchemy/engine/create.py", line 518, in create_engine
    entrypoint = u._get_entrypoint()
  File "/home/airflow/.local/lib/python3.7/site-packages/sqlalchemy/engine/url.py", line 662, in _get_entrypoint
    cls = registry.load(name)
  File "/home/airflow/.local/lib/python3.7/site-packages/sqlalchemy/util/langhelpers.py", line 344, in load
    "Can't load plugin: %s:%s" % (self.group, name)
sqlalchemy.exc.NoSuchModuleError: Can't load plugin: sqlalchemy.dialects:postgres
[2023-07-10T04:11:37.400+0000] {taskinstance.py:1350} INFO - Marking task as UP_FOR_RETRY. dag_id=etl_uber_data, task_id=load_postgres, execution_date=20230710T024419, start_date=20230710T041135, end_date=20230710T041137
[2023-07-10T04:11:37.410+0000] {standard_task_runner.py:109} ERROR - Failed to execute job 45 for task load_postgres (Can't load plugin: sqlalchemy.dialects:postgres; 5701)
[2023-07-10T04:11:37.450+0000] {local_task_job_runner.py:225} INFO - Task exited with return code 1
[2023-07-10T04:11:37.466+0000] {taskinstance.py:2653} INFO - 0 downstream tasks scheduled from follow-on schedule check
