[2023-07-10T08:57:08.905+0000] {taskinstance.py:1103} INFO - Dependencies all met for dep_context=non-requeueable deps ti=<TaskInstance: etl_uber_data.transform_pickup_location_dim manual__2023-07-10T02:44:19.817965+00:00 [queued]>
[2023-07-10T08:57:08.916+0000] {taskinstance.py:1103} INFO - Dependencies all met for dep_context=requeueable deps ti=<TaskInstance: etl_uber_data.transform_pickup_location_dim manual__2023-07-10T02:44:19.817965+00:00 [queued]>
[2023-07-10T08:57:08.916+0000] {taskinstance.py:1308} INFO - Starting attempt 25 of 26
[2023-07-10T08:57:08.944+0000] {taskinstance.py:1327} INFO - Executing <Task(PythonOperator): transform_pickup_location_dim> on 2023-07-10 02:44:19.817965+00:00
[2023-07-10T08:57:08.950+0000] {standard_task_runner.py:57} INFO - Started process 27205 to run task
[2023-07-10T08:57:08.956+0000] {standard_task_runner.py:84} INFO - Running: ['***', 'tasks', 'run', 'etl_uber_data', 'transform_pickup_location_dim', 'manual__2023-07-10T02:44:19.817965+00:00', '--job-id', '325', '--raw', '--subdir', 'DAGS_FOLDER/etl_uber_data.py', '--cfg-path', '/tmp/tmpgjfh3sly']
[2023-07-10T08:57:08.959+0000] {standard_task_runner.py:85} INFO - Job 325: Subtask transform_pickup_location_dim
[2023-07-10T08:57:09.020+0000] {task_command.py:410} INFO - Running <TaskInstance: etl_uber_data.transform_pickup_location_dim manual__2023-07-10T02:44:19.817965+00:00 [running]> on host 1481ab9bb806
[2023-07-10T08:57:09.115+0000] {taskinstance.py:1547} INFO - Exporting env vars: AIRFLOW_CTX_DAG_OWNER='Mervyn Frost' AIRFLOW_CTX_DAG_ID='etl_uber_data' AIRFLOW_CTX_TASK_ID='transform_pickup_location_dim' AIRFLOW_CTX_EXECUTION_DATE='2023-07-10T02:44:19.817965+00:00' AIRFLOW_CTX_TRY_NUMBER='25' AIRFLOW_CTX_DAG_RUN_ID='manual__2023-07-10T02:44:19.817965+00:00'
[2023-07-10T08:57:09.129+0000] {taskinstance.py:1824} ERROR - Task failed with exception
Traceback (most recent call last):
  File "/home/airflow/.local/lib/python3.7/site-packages/airflow/operators/python.py", line 181, in execute
    return_value = self.execute_callable()
  File "/home/airflow/.local/lib/python3.7/site-packages/airflow/operators/python.py", line 198, in execute_callable
    return self.python_callable(*self.op_args, **self.op_kwargs)
  File "/opt/airflow/dags/etl_uber_data.py", line 102, in transform_pickup_location_dim
    pickup_location_dim = df[['pickup_longitude','pickup_latitude']].reset_index(drop=True)
NameError: name 'df' is not defined
[2023-07-10T08:57:09.142+0000] {taskinstance.py:1350} INFO - Marking task as UP_FOR_RETRY. dag_id=etl_uber_data, task_id=transform_pickup_location_dim, execution_date=20230710T024419, start_date=20230710T085708, end_date=20230710T085709
[2023-07-10T08:57:09.154+0000] {standard_task_runner.py:109} ERROR - Failed to execute job 325 for task transform_pickup_location_dim (name 'df' is not defined; 27205)
[2023-07-10T08:57:09.169+0000] {local_task_job_runner.py:225} INFO - Task exited with return code 1
[2023-07-10T08:57:09.266+0000] {taskinstance.py:2653} INFO - 0 downstream tasks scheduled from follow-on schedule check
