[2023-07-10T09:02:10.150+0000] {taskinstance.py:1103} INFO - Dependencies all met for dep_context=non-requeueable deps ti=<TaskInstance: etl_uber_data.transform_trip_distance_dim manual__2023-07-10T02:44:19.817965+00:00 [queued]>
[2023-07-10T09:02:10.162+0000] {taskinstance.py:1103} INFO - Dependencies all met for dep_context=requeueable deps ti=<TaskInstance: etl_uber_data.transform_trip_distance_dim manual__2023-07-10T02:44:19.817965+00:00 [queued]>
[2023-07-10T09:02:10.163+0000] {taskinstance.py:1308} INFO - Starting attempt 26 of 26
[2023-07-10T09:02:10.182+0000] {taskinstance.py:1327} INFO - Executing <Task(PythonOperator): transform_trip_distance_dim> on 2023-07-10 02:44:19.817965+00:00
[2023-07-10T09:02:10.187+0000] {standard_task_runner.py:57} INFO - Started process 27597 to run task
[2023-07-10T09:02:10.191+0000] {standard_task_runner.py:84} INFO - Running: ['***', 'tasks', 'run', 'etl_uber_data', 'transform_trip_distance_dim', 'manual__2023-07-10T02:44:19.817965+00:00', '--job-id', '328', '--raw', '--subdir', 'DAGS_FOLDER/etl_uber_data.py', '--cfg-path', '/tmp/tmplisgykhk']
[2023-07-10T09:02:10.195+0000] {standard_task_runner.py:85} INFO - Job 328: Subtask transform_trip_distance_dim
[2023-07-10T09:02:10.250+0000] {task_command.py:410} INFO - Running <TaskInstance: etl_uber_data.transform_trip_distance_dim manual__2023-07-10T02:44:19.817965+00:00 [running]> on host 1481ab9bb806
[2023-07-10T09:02:10.345+0000] {taskinstance.py:1547} INFO - Exporting env vars: AIRFLOW_CTX_DAG_OWNER='Mervyn Frost' AIRFLOW_CTX_DAG_ID='etl_uber_data' AIRFLOW_CTX_TASK_ID='transform_trip_distance_dim' AIRFLOW_CTX_EXECUTION_DATE='2023-07-10T02:44:19.817965+00:00' AIRFLOW_CTX_TRY_NUMBER='26' AIRFLOW_CTX_DAG_RUN_ID='manual__2023-07-10T02:44:19.817965+00:00'
[2023-07-10T09:02:10.489+0000] {taskinstance.py:1824} ERROR - Task failed with exception
Traceback (most recent call last):
  File "/home/airflow/.local/lib/python3.7/site-packages/airflow/operators/python.py", line 181, in execute
    return_value = self.execute_callable()
  File "/home/airflow/.local/lib/python3.7/site-packages/airflow/operators/python.py", line 198, in execute_callable
    return self.python_callable(*self.op_args, **self.op_kwargs)
  File "/opt/airflow/dags/etl_uber_data.py", line 75, in transform_trip_distance_dim
    trip_distance_dim = df[['trip_distance']].reset_index(drop=True)
NameError: name 'df' is not defined
[2023-07-10T09:02:10.506+0000] {taskinstance.py:1350} INFO - Marking task as FAILED. dag_id=etl_uber_data, task_id=transform_trip_distance_dim, execution_date=20230710T024419, start_date=20230710T090210, end_date=20230710T090210
[2023-07-10T09:02:10.521+0000] {standard_task_runner.py:109} ERROR - Failed to execute job 328 for task transform_trip_distance_dim (name 'df' is not defined; 27597)
[2023-07-10T09:02:10.563+0000] {local_task_job_runner.py:225} INFO - Task exited with return code 1
[2023-07-10T09:02:10.596+0000] {taskinstance.py:2653} INFO - 0 downstream tasks scheduled from follow-on schedule check
