[2023-07-10T09:19:26.373+0000] {taskinstance.py:1103} INFO - Dependencies all met for dep_context=non-requeueable deps ti=<TaskInstance: etl_uber_data.transform_payment_type_dim manual__2023-07-10T02:44:19.817965+00:00 [queued]>
[2023-07-10T09:19:26.388+0000] {taskinstance.py:1103} INFO - Dependencies all met for dep_context=requeueable deps ti=<TaskInstance: etl_uber_data.transform_payment_type_dim manual__2023-07-10T02:44:19.817965+00:00 [queued]>
[2023-07-10T09:19:26.389+0000] {taskinstance.py:1308} INFO - Starting attempt 33 of 34
[2023-07-10T09:19:26.409+0000] {taskinstance.py:1327} INFO - Executing <Task(PythonOperator): transform_payment_type_dim> on 2023-07-10 02:44:19.817965+00:00
[2023-07-10T09:19:26.416+0000] {standard_task_runner.py:57} INFO - Started process 30182 to run task
[2023-07-10T09:19:26.419+0000] {standard_task_runner.py:84} INFO - Running: ['***', 'tasks', 'run', 'etl_uber_data', 'transform_payment_type_dim', 'manual__2023-07-10T02:44:19.817965+00:00', '--job-id', '406', '--raw', '--subdir', 'DAGS_FOLDER/etl_uber_data.py', '--cfg-path', '/tmp/tmpr25vzbur']
[2023-07-10T09:19:26.422+0000] {standard_task_runner.py:85} INFO - Job 406: Subtask transform_payment_type_dim
[2023-07-10T09:19:26.485+0000] {task_command.py:410} INFO - Running <TaskInstance: etl_uber_data.transform_payment_type_dim manual__2023-07-10T02:44:19.817965+00:00 [running]> on host 1481ab9bb806
[2023-07-10T09:19:26.578+0000] {taskinstance.py:1547} INFO - Exporting env vars: AIRFLOW_CTX_DAG_OWNER='Mervyn Frost' AIRFLOW_CTX_DAG_ID='etl_uber_data' AIRFLOW_CTX_TASK_ID='transform_payment_type_dim' AIRFLOW_CTX_EXECUTION_DATE='2023-07-10T02:44:19.817965+00:00' AIRFLOW_CTX_TRY_NUMBER='33' AIRFLOW_CTX_DAG_RUN_ID='manual__2023-07-10T02:44:19.817965+00:00'
[2023-07-10T09:19:26.596+0000] {taskinstance.py:1824} ERROR - Task failed with exception
Traceback (most recent call last):
  File "/home/airflow/.local/lib/python3.7/site-packages/airflow/operators/python.py", line 181, in execute
    return_value = self.execute_callable()
  File "/home/airflow/.local/lib/python3.7/site-packages/airflow/operators/python.py", line 198, in execute_callable
    return self.python_callable(*self.op_args, **self.op_kwargs)
  File "/opt/airflow/dags/etl_uber_data.py", line 128, in transform_payment_type_dim
    payment_type_dim = df[['payment_type']].reset_index(drop=True)
TypeError: 'NoneType' object is not subscriptable
[2023-07-10T09:19:26.610+0000] {taskinstance.py:1350} INFO - Marking task as UP_FOR_RETRY. dag_id=etl_uber_data, task_id=transform_payment_type_dim, execution_date=20230710T024419, start_date=20230710T091926, end_date=20230710T091926
[2023-07-10T09:19:26.629+0000] {standard_task_runner.py:109} ERROR - Failed to execute job 406 for task transform_payment_type_dim ('NoneType' object is not subscriptable; 30182)
[2023-07-10T09:19:26.673+0000] {local_task_job_runner.py:225} INFO - Task exited with return code 1
[2023-07-10T09:19:26.764+0000] {taskinstance.py:2653} INFO - 0 downstream tasks scheduled from follow-on schedule check
