[2023-07-10T09:03:15.476+0000] {taskinstance.py:1103} INFO - Dependencies all met for dep_context=non-requeueable deps ti=<TaskInstance: etl_uber_data.transform_passenger_count_dim manual__2023-07-10T02:44:19.817965+00:00 [queued]>
[2023-07-10T09:03:15.490+0000] {taskinstance.py:1103} INFO - Dependencies all met for dep_context=requeueable deps ti=<TaskInstance: etl_uber_data.transform_passenger_count_dim manual__2023-07-10T02:44:19.817965+00:00 [queued]>
[2023-07-10T09:03:15.491+0000] {taskinstance.py:1308} INFO - Starting attempt 28 of 29
[2023-07-10T09:03:15.524+0000] {taskinstance.py:1327} INFO - Executing <Task(PythonOperator): transform_passenger_count_dim> on 2023-07-10 02:44:19.817965+00:00
[2023-07-10T09:03:15.615+0000] {standard_task_runner.py:57} INFO - Started process 27924 to run task
[2023-07-10T09:03:15.630+0000] {standard_task_runner.py:84} INFO - Running: ['***', 'tasks', 'run', 'etl_uber_data', 'transform_passenger_count_dim', 'manual__2023-07-10T02:44:19.817965+00:00', '--job-id', '338', '--raw', '--subdir', 'DAGS_FOLDER/etl_uber_data.py', '--cfg-path', '/tmp/tmpief9ec5y']
[2023-07-10T09:03:15.637+0000] {standard_task_runner.py:85} INFO - Job 338: Subtask transform_passenger_count_dim
[2023-07-10T09:03:15.716+0000] {task_command.py:410} INFO - Running <TaskInstance: etl_uber_data.transform_passenger_count_dim manual__2023-07-10T02:44:19.817965+00:00 [running]> on host 1481ab9bb806
[2023-07-10T09:03:15.807+0000] {taskinstance.py:1547} INFO - Exporting env vars: AIRFLOW_CTX_DAG_OWNER='Mervyn Frost' AIRFLOW_CTX_DAG_ID='etl_uber_data' AIRFLOW_CTX_TASK_ID='transform_passenger_count_dim' AIRFLOW_CTX_EXECUTION_DATE='2023-07-10T02:44:19.817965+00:00' AIRFLOW_CTX_TRY_NUMBER='28' AIRFLOW_CTX_DAG_RUN_ID='manual__2023-07-10T02:44:19.817965+00:00'
[2023-07-10T09:03:15.824+0000] {taskinstance.py:1824} ERROR - Task failed with exception
Traceback (most recent call last):
  File "/home/airflow/.local/lib/python3.7/site-packages/airflow/operators/python.py", line 181, in execute
    return_value = self.execute_callable()
  File "/home/airflow/.local/lib/python3.7/site-packages/airflow/operators/python.py", line 198, in execute_callable
    return self.python_callable(*self.op_args, **self.op_kwargs)
  File "/opt/airflow/dags/etl_uber_data.py", line 66, in transform_passenger_count_dim
    passenger_count_dim = df[['passenger_count']].reset_index(drop=True)
TypeError: 'NoneType' object is not subscriptable
[2023-07-10T09:03:15.841+0000] {taskinstance.py:1350} INFO - Marking task as UP_FOR_RETRY. dag_id=etl_uber_data, task_id=transform_passenger_count_dim, execution_date=20230710T024419, start_date=20230710T090315, end_date=20230710T090315
[2023-07-10T09:03:15.860+0000] {standard_task_runner.py:109} ERROR - Failed to execute job 338 for task transform_passenger_count_dim ('NoneType' object is not subscriptable; 27924)
[2023-07-10T09:03:15.882+0000] {local_task_job_runner.py:225} INFO - Task exited with return code 1
[2023-07-10T09:03:15.951+0000] {taskinstance.py:2653} INFO - 0 downstream tasks scheduled from follow-on schedule check
