[2023-07-10T03:03:19.695+0000] {taskinstance.py:1103} INFO - Dependencies all met for dep_context=non-requeueable deps ti=<TaskInstance: etl_uber_data.transform manual__2023-07-10T02:53:45.112070+00:00 [queued]>
[2023-07-10T03:03:19.703+0000] {taskinstance.py:1103} INFO - Dependencies all met for dep_context=requeueable deps ti=<TaskInstance: etl_uber_data.transform manual__2023-07-10T02:53:45.112070+00:00 [queued]>
[2023-07-10T03:03:19.703+0000] {taskinstance.py:1308} INFO - Starting attempt 7 of 8
[2023-07-10T03:03:19.714+0000] {taskinstance.py:1327} INFO - Executing <Task(PythonOperator): transform> on 2023-07-10 02:53:45.112070+00:00
[2023-07-10T03:03:19.719+0000] {standard_task_runner.py:57} INFO - Started process 2034 to run task
[2023-07-10T03:03:19.721+0000] {standard_task_runner.py:84} INFO - Running: ['***', 'tasks', 'run', 'etl_uber_data', 'transform', 'manual__2023-07-10T02:53:45.112070+00:00', '--job-id', '27', '--raw', '--subdir', 'DAGS_FOLDER/etl_uber_data.py', '--cfg-path', '/tmp/tmp1kwvn0at']
[2023-07-10T03:03:19.723+0000] {standard_task_runner.py:85} INFO - Job 27: Subtask transform
[2023-07-10T03:03:19.761+0000] {task_command.py:410} INFO - Running <TaskInstance: etl_uber_data.transform manual__2023-07-10T02:53:45.112070+00:00 [running]> on host 1481ab9bb806
[2023-07-10T03:03:19.824+0000] {taskinstance.py:1547} INFO - Exporting env vars: AIRFLOW_CTX_DAG_OWNER='Mervyn Frost' AIRFLOW_CTX_DAG_ID='etl_uber_data' AIRFLOW_CTX_TASK_ID='transform' AIRFLOW_CTX_EXECUTION_DATE='2023-07-10T02:53:45.112070+00:00' AIRFLOW_CTX_TRY_NUMBER='7' AIRFLOW_CTX_DAG_RUN_ID='manual__2023-07-10T02:53:45.112070+00:00'
[2023-07-10T03:03:19.825+0000] {taskinstance.py:1824} ERROR - Task failed with exception
Traceback (most recent call last):
  File "/home/airflow/.local/lib/python3.7/site-packages/airflow/operators/python.py", line 181, in execute
    return_value = self.execute_callable()
  File "/home/airflow/.local/lib/python3.7/site-packages/airflow/operators/python.py", line 198, in execute_callable
    return self.python_callable(*self.op_args, **self.op_kwargs)
TypeError: transform() missing 1 required positional argument: 'dataframe'
[2023-07-10T03:03:19.833+0000] {taskinstance.py:1350} INFO - Marking task as UP_FOR_RETRY. dag_id=etl_uber_data, task_id=transform, execution_date=20230710T025345, start_date=20230710T030319, end_date=20230710T030319
[2023-07-10T03:03:19.842+0000] {standard_task_runner.py:109} ERROR - Failed to execute job 27 for task transform (transform() missing 1 required positional argument: 'dataframe'; 2034)
[2023-07-10T03:03:19.854+0000] {local_task_job_runner.py:225} INFO - Task exited with return code 1
[2023-07-10T03:03:19.866+0000] {taskinstance.py:2653} INFO - 0 downstream tasks scheduled from follow-on schedule check
