[2023-07-10T03:01:26.145+0000] {taskinstance.py:1103} INFO - Dependencies all met for dep_context=non-requeueable deps ti=<TaskInstance: etl_uber_data.transform manual__2023-07-10T02:53:45.112070+00:00 [queued]>
[2023-07-10T03:01:26.153+0000] {taskinstance.py:1103} INFO - Dependencies all met for dep_context=requeueable deps ti=<TaskInstance: etl_uber_data.transform manual__2023-07-10T02:53:45.112070+00:00 [queued]>
[2023-07-10T03:01:26.154+0000] {taskinstance.py:1308} INFO - Starting attempt 6 of 7
[2023-07-10T03:01:26.165+0000] {taskinstance.py:1327} INFO - Executing <Task(PythonOperator): transform> on 2023-07-10 02:53:45.112070+00:00
[2023-07-10T03:01:26.170+0000] {standard_task_runner.py:57} INFO - Started process 1917 to run task
[2023-07-10T03:01:26.172+0000] {standard_task_runner.py:84} INFO - Running: ['***', 'tasks', 'run', 'etl_uber_data', 'transform', 'manual__2023-07-10T02:53:45.112070+00:00', '--job-id', '25', '--raw', '--subdir', 'DAGS_FOLDER/etl_uber_data.py', '--cfg-path', '/tmp/tmpc20k0maa']
[2023-07-10T03:01:26.174+0000] {standard_task_runner.py:85} INFO - Job 25: Subtask transform
[2023-07-10T03:01:26.213+0000] {task_command.py:410} INFO - Running <TaskInstance: etl_uber_data.transform manual__2023-07-10T02:53:45.112070+00:00 [running]> on host 1481ab9bb806
[2023-07-10T03:01:26.277+0000] {taskinstance.py:1547} INFO - Exporting env vars: AIRFLOW_CTX_DAG_OWNER='Mervyn Frost' AIRFLOW_CTX_DAG_ID='etl_uber_data' AIRFLOW_CTX_TASK_ID='transform' AIRFLOW_CTX_EXECUTION_DATE='2023-07-10T02:53:45.112070+00:00' AIRFLOW_CTX_TRY_NUMBER='6' AIRFLOW_CTX_DAG_RUN_ID='manual__2023-07-10T02:53:45.112070+00:00'
[2023-07-10T03:01:26.278+0000] {taskinstance.py:1824} ERROR - Task failed with exception
Traceback (most recent call last):
  File "/home/airflow/.local/lib/python3.7/site-packages/airflow/operators/python.py", line 181, in execute
    return_value = self.execute_callable()
  File "/home/airflow/.local/lib/python3.7/site-packages/airflow/operators/python.py", line 198, in execute_callable
    return self.python_callable(*self.op_args, **self.op_kwargs)
  File "/opt/airflow/dags/etl_uber_data.py", line 24, in transform
    df = df.xcoms_pull(task_ids='extract')
UnboundLocalError: local variable 'df' referenced before assignment
[2023-07-10T03:01:26.288+0000] {taskinstance.py:1350} INFO - Marking task as UP_FOR_RETRY. dag_id=etl_uber_data, task_id=transform, execution_date=20230710T025345, start_date=20230710T030126, end_date=20230710T030126
[2023-07-10T03:01:26.297+0000] {standard_task_runner.py:109} ERROR - Failed to execute job 25 for task transform (local variable 'df' referenced before assignment; 1917)
[2023-07-10T03:01:26.304+0000] {local_task_job_runner.py:225} INFO - Task exited with return code 1
[2023-07-10T03:01:26.317+0000] {taskinstance.py:2653} INFO - 0 downstream tasks scheduled from follow-on schedule check
