[2023-07-10T02:57:37.501+0000] {taskinstance.py:1103} INFO - Dependencies all met for dep_context=non-requeueable deps ti=<TaskInstance: etl_uber_data.transform manual__2023-07-10T02:53:45.112070+00:00 [queued]>
[2023-07-10T02:57:37.509+0000] {taskinstance.py:1103} INFO - Dependencies all met for dep_context=requeueable deps ti=<TaskInstance: etl_uber_data.transform manual__2023-07-10T02:53:45.112070+00:00 [queued]>
[2023-07-10T02:57:37.510+0000] {taskinstance.py:1308} INFO - Starting attempt 3 of 4
[2023-07-10T02:57:37.521+0000] {taskinstance.py:1327} INFO - Executing <Task(PythonOperator): transform> on 2023-07-10 02:53:45.112070+00:00
[2023-07-10T02:57:37.526+0000] {standard_task_runner.py:57} INFO - Started process 1586 to run task
[2023-07-10T02:57:37.529+0000] {standard_task_runner.py:84} INFO - Running: ['***', 'tasks', 'run', 'etl_uber_data', 'transform', 'manual__2023-07-10T02:53:45.112070+00:00', '--job-id', '18', '--raw', '--subdir', 'DAGS_FOLDER/etl_uber_data.py', '--cfg-path', '/tmp/tmpjve1uj6e']
[2023-07-10T02:57:37.530+0000] {standard_task_runner.py:85} INFO - Job 18: Subtask transform
[2023-07-10T02:57:37.569+0000] {task_command.py:410} INFO - Running <TaskInstance: etl_uber_data.transform manual__2023-07-10T02:53:45.112070+00:00 [running]> on host 1481ab9bb806
[2023-07-10T02:57:37.632+0000] {taskinstance.py:1547} INFO - Exporting env vars: AIRFLOW_CTX_DAG_OWNER='Mervyn Frost' AIRFLOW_CTX_DAG_ID='etl_uber_data' AIRFLOW_CTX_TASK_ID='transform' AIRFLOW_CTX_EXECUTION_DATE='2023-07-10T02:53:45.112070+00:00' AIRFLOW_CTX_TRY_NUMBER='3' AIRFLOW_CTX_DAG_RUN_ID='manual__2023-07-10T02:53:45.112070+00:00'
[2023-07-10T02:57:37.633+0000] {taskinstance.py:1824} ERROR - Task failed with exception
Traceback (most recent call last):
  File "/home/airflow/.local/lib/python3.7/site-packages/airflow/operators/python.py", line 181, in execute
    return_value = self.execute_callable()
  File "/home/airflow/.local/lib/python3.7/site-packages/airflow/operators/python.py", line 198, in execute_callable
    return self.python_callable(*self.op_args, **self.op_kwargs)
TypeError: transform() missing 1 required positional argument: 'df'
[2023-07-10T02:57:37.640+0000] {taskinstance.py:1350} INFO - Marking task as UP_FOR_RETRY. dag_id=etl_uber_data, task_id=transform, execution_date=20230710T025345, start_date=20230710T025737, end_date=20230710T025737
[2023-07-10T02:57:37.649+0000] {standard_task_runner.py:109} ERROR - Failed to execute job 18 for task transform (transform() missing 1 required positional argument: 'df'; 1586)
[2023-07-10T02:57:37.661+0000] {local_task_job_runner.py:225} INFO - Task exited with return code 1
[2023-07-10T02:57:37.674+0000] {taskinstance.py:2653} INFO - 0 downstream tasks scheduled from follow-on schedule check
