[2023-07-10T04:34:46.299+0000] {taskinstance.py:1103} INFO - Dependencies all met for dep_context=non-requeueable deps ti=<TaskInstance: etl_uber_data.transform_fact_table manual__2023-07-10T02:44:19.817965+00:00 [queued]>
[2023-07-10T04:34:46.307+0000] {taskinstance.py:1103} INFO - Dependencies all met for dep_context=requeueable deps ti=<TaskInstance: etl_uber_data.transform_fact_table manual__2023-07-10T02:44:19.817965+00:00 [queued]>
[2023-07-10T04:34:46.308+0000] {taskinstance.py:1308} INFO - Starting attempt 2 of 3
[2023-07-10T04:34:46.319+0000] {taskinstance.py:1327} INFO - Executing <Task(PythonOperator): transform_fact_table> on 2023-07-10 02:44:19.817965+00:00
[2023-07-10T04:34:46.324+0000] {standard_task_runner.py:57} INFO - Started process 7180 to run task
[2023-07-10T04:34:46.326+0000] {standard_task_runner.py:84} INFO - Running: ['***', 'tasks', 'run', 'etl_uber_data', 'transform_fact_table', 'manual__2023-07-10T02:44:19.817965+00:00', '--job-id', '57', '--raw', '--subdir', 'DAGS_FOLDER/etl_uber_data.py', '--cfg-path', '/tmp/tmp89mj5s3r']
[2023-07-10T04:34:46.328+0000] {standard_task_runner.py:85} INFO - Job 57: Subtask transform_fact_table
[2023-07-10T04:34:46.368+0000] {task_command.py:410} INFO - Running <TaskInstance: etl_uber_data.transform_fact_table manual__2023-07-10T02:44:19.817965+00:00 [running]> on host 1481ab9bb806
[2023-07-10T04:34:46.429+0000] {taskinstance.py:1547} INFO - Exporting env vars: AIRFLOW_CTX_DAG_OWNER='Mervyn Frost' AIRFLOW_CTX_DAG_ID='etl_uber_data' AIRFLOW_CTX_TASK_ID='transform_fact_table' AIRFLOW_CTX_EXECUTION_DATE='2023-07-10T02:44:19.817965+00:00' AIRFLOW_CTX_TRY_NUMBER='2' AIRFLOW_CTX_DAG_RUN_ID='manual__2023-07-10T02:44:19.817965+00:00'
[2023-07-10T04:34:46.725+0000] {taskinstance.py:1824} ERROR - Task failed with exception
Traceback (most recent call last):
  File "/home/airflow/.local/lib/python3.7/site-packages/airflow/operators/python.py", line 181, in execute
    return_value = self.execute_callable()
  File "/home/airflow/.local/lib/python3.7/site-packages/airflow/operators/python.py", line 198, in execute_callable
    return self.python_callable(*self.op_args, **self.op_kwargs)
  File "/opt/airflow/dags/etl_uber_data.py", line 134, in transform_fact_table
    fact_table = df.merge(datetime_dim, left_on='trip_id', right_on='datetime_id') \
  File "/home/airflow/.local/lib/python3.7/site-packages/pandas/core/frame.py", line 9203, in merge
    validate=validate,
  File "/home/airflow/.local/lib/python3.7/site-packages/pandas/core/reshape/merge.py", line 119, in merge
    validate=validate,
  File "/home/airflow/.local/lib/python3.7/site-packages/pandas/core/reshape/merge.py", line 628, in __init__
    _right = _validate_operand(right)
  File "/home/airflow/.local/lib/python3.7/site-packages/pandas/core/reshape/merge.py", line 2283, in _validate_operand
    f"Can only merge Series or DataFrame objects, a {type(obj)} was passed"
TypeError: Can only merge Series or DataFrame objects, a <class 'NoneType'> was passed
[2023-07-10T04:34:46.736+0000] {taskinstance.py:1350} INFO - Marking task as UP_FOR_RETRY. dag_id=etl_uber_data, task_id=transform_fact_table, execution_date=20230710T024419, start_date=20230710T043446, end_date=20230710T043446
[2023-07-10T04:34:46.745+0000] {standard_task_runner.py:109} ERROR - Failed to execute job 57 for task transform_fact_table (Can only merge Series or DataFrame objects, a <class 'NoneType'> was passed; 7180)
[2023-07-10T04:34:46.781+0000] {local_task_job_runner.py:225} INFO - Task exited with return code 1
[2023-07-10T04:34:46.803+0000] {taskinstance.py:2653} INFO - 0 downstream tasks scheduled from follow-on schedule check
