[2023-07-10T08:25:51.467+0000] {taskinstance.py:1103} INFO - Dependencies all met for dep_context=non-requeueable deps ti=<TaskInstance: etl_uber_data.transform_date_time_dim manual__2023-07-10T02:44:19.817965+00:00 [queued]>
[2023-07-10T08:25:51.482+0000] {taskinstance.py:1103} INFO - Dependencies all met for dep_context=requeueable deps ti=<TaskInstance: etl_uber_data.transform_date_time_dim manual__2023-07-10T02:44:19.817965+00:00 [queued]>
[2023-07-10T08:25:51.483+0000] {taskinstance.py:1308} INFO - Starting attempt 15 of 16
[2023-07-10T08:25:51.505+0000] {taskinstance.py:1327} INFO - Executing <Task(PythonOperator): transform_date_time_dim> on 2023-07-10 02:44:19.817965+00:00
[2023-07-10T08:25:51.510+0000] {standard_task_runner.py:57} INFO - Started process 22059 to run task
[2023-07-10T08:25:51.515+0000] {standard_task_runner.py:84} INFO - Running: ['***', 'tasks', 'run', 'etl_uber_data', 'transform_date_time_dim', 'manual__2023-07-10T02:44:19.817965+00:00', '--job-id', '193', '--raw', '--subdir', 'DAGS_FOLDER/etl_uber_data.py', '--cfg-path', '/tmp/tmpziejiva2']
[2023-07-10T08:25:51.518+0000] {standard_task_runner.py:85} INFO - Job 193: Subtask transform_date_time_dim
[2023-07-10T08:25:51.582+0000] {task_command.py:410} INFO - Running <TaskInstance: etl_uber_data.transform_date_time_dim manual__2023-07-10T02:44:19.817965+00:00 [running]> on host 1481ab9bb806
[2023-07-10T08:25:51.680+0000] {taskinstance.py:1547} INFO - Exporting env vars: AIRFLOW_CTX_DAG_OWNER='Mervyn Frost' AIRFLOW_CTX_DAG_ID='etl_uber_data' AIRFLOW_CTX_TASK_ID='transform_date_time_dim' AIRFLOW_CTX_EXECUTION_DATE='2023-07-10T02:44:19.817965+00:00' AIRFLOW_CTX_TRY_NUMBER='15' AIRFLOW_CTX_DAG_RUN_ID='manual__2023-07-10T02:44:19.817965+00:00'
[2023-07-10T08:25:52.056+0000] {taskinstance.py:1824} ERROR - Task failed with exception
Traceback (most recent call last):
  File "/home/airflow/.local/lib/python3.7/site-packages/airflow/operators/python.py", line 181, in execute
    return_value = self.execute_callable()
  File "/home/airflow/.local/lib/python3.7/site-packages/airflow/operators/python.py", line 198, in execute_callable
    return self.python_callable(*self.op_args, **self.op_kwargs)
  File "/opt/airflow/dags/etl_uber_data.py", line 55, in transform_date_time_dim
    pritn(type(datetime_dim))
NameError: name 'pritn' is not defined
[2023-07-10T08:25:52.067+0000] {taskinstance.py:1350} INFO - Marking task as UP_FOR_RETRY. dag_id=etl_uber_data, task_id=transform_date_time_dim, execution_date=20230710T024419, start_date=20230710T082551, end_date=20230710T082552
[2023-07-10T08:25:52.077+0000] {standard_task_runner.py:109} ERROR - Failed to execute job 193 for task transform_date_time_dim (name 'pritn' is not defined; 22059)
[2023-07-10T08:25:52.128+0000] {local_task_job_runner.py:225} INFO - Task exited with return code 1
[2023-07-10T08:25:52.156+0000] {taskinstance.py:2653} INFO - 0 downstream tasks scheduled from follow-on schedule check
