[2023-07-10T09:09:24.913+0000] {taskinstance.py:1103} INFO - Dependencies all met for dep_context=non-requeueable deps ti=<TaskInstance: etl_uber_data.transform_date_time_dim manual__2023-07-10T02:44:19.817965+00:00 [queued]>
[2023-07-10T09:09:24.923+0000] {taskinstance.py:1103} INFO - Dependencies all met for dep_context=requeueable deps ti=<TaskInstance: etl_uber_data.transform_date_time_dim manual__2023-07-10T02:44:19.817965+00:00 [queued]>
[2023-07-10T09:09:24.924+0000] {taskinstance.py:1308} INFO - Starting attempt 32 of 33
[2023-07-10T09:09:24.941+0000] {taskinstance.py:1327} INFO - Executing <Task(PythonOperator): transform_date_time_dim> on 2023-07-10 02:44:19.817965+00:00
[2023-07-10T09:09:24.946+0000] {standard_task_runner.py:57} INFO - Started process 28708 to run task
[2023-07-10T09:09:24.952+0000] {standard_task_runner.py:84} INFO - Running: ['***', 'tasks', 'run', 'etl_uber_data', 'transform_date_time_dim', 'manual__2023-07-10T02:44:19.817965+00:00', '--job-id', '359', '--raw', '--subdir', 'DAGS_FOLDER/etl_uber_data.py', '--cfg-path', '/tmp/tmp0vt10ifk']
[2023-07-10T09:09:24.955+0000] {standard_task_runner.py:85} INFO - Job 359: Subtask transform_date_time_dim
[2023-07-10T09:09:25.023+0000] {task_command.py:410} INFO - Running <TaskInstance: etl_uber_data.transform_date_time_dim manual__2023-07-10T02:44:19.817965+00:00 [running]> on host 1481ab9bb806
[2023-07-10T09:09:25.136+0000] {taskinstance.py:1547} INFO - Exporting env vars: AIRFLOW_CTX_DAG_OWNER='Mervyn Frost' AIRFLOW_CTX_DAG_ID='etl_uber_data' AIRFLOW_CTX_TASK_ID='transform_date_time_dim' AIRFLOW_CTX_EXECUTION_DATE='2023-07-10T02:44:19.817965+00:00' AIRFLOW_CTX_TRY_NUMBER='32' AIRFLOW_CTX_DAG_RUN_ID='manual__2023-07-10T02:44:19.817965+00:00'
[2023-07-10T09:09:25.151+0000] {taskinstance.py:1824} ERROR - Task failed with exception
Traceback (most recent call last):
  File "/home/airflow/.local/lib/python3.7/site-packages/airflow/operators/python.py", line 181, in execute
    return_value = self.execute_callable()
  File "/home/airflow/.local/lib/python3.7/site-packages/airflow/operators/python.py", line 198, in execute_callable
    return self.python_callable(*self.op_args, **self.op_kwargs)
  File "/opt/airflow/dags/etl_uber_data.py", line 37, in transform_date_time_dim
    df['tpep_pickup_datetime'] = pd.to_datetime(df['tpep_pickup_datetime'])
TypeError: 'NoneType' object is not subscriptable
[2023-07-10T09:09:25.169+0000] {taskinstance.py:1350} INFO - Marking task as UP_FOR_RETRY. dag_id=etl_uber_data, task_id=transform_date_time_dim, execution_date=20230710T024419, start_date=20230710T090924, end_date=20230710T090925
[2023-07-10T09:09:25.185+0000] {standard_task_runner.py:109} ERROR - Failed to execute job 359 for task transform_date_time_dim ('NoneType' object is not subscriptable; 28708)
[2023-07-10T09:09:25.203+0000] {local_task_job_runner.py:225} INFO - Task exited with return code 1
[2023-07-10T09:09:25.257+0000] {taskinstance.py:2653} INFO - 0 downstream tasks scheduled from follow-on schedule check
