[2023-07-10T03:58:58.626+0000] {taskinstance.py:1103} INFO - Dependencies all met for dep_context=non-requeueable deps ti=<TaskInstance: etl_uber_data.transform manual__2023-07-10T02:44:19.817965+00:00 [queued]>
[2023-07-10T03:58:58.635+0000] {taskinstance.py:1103} INFO - Dependencies all met for dep_context=requeueable deps ti=<TaskInstance: etl_uber_data.transform manual__2023-07-10T02:44:19.817965+00:00 [queued]>
[2023-07-10T03:58:58.636+0000] {taskinstance.py:1308} INFO - Starting attempt 9 of 10
[2023-07-10T03:58:58.649+0000] {taskinstance.py:1327} INFO - Executing <Task(PythonOperator): transform> on 2023-07-10 02:44:19.817965+00:00
[2023-07-10T03:58:58.656+0000] {standard_task_runner.py:57} INFO - Started process 4919 to run task
[2023-07-10T03:58:58.658+0000] {standard_task_runner.py:84} INFO - Running: ['***', 'tasks', 'run', 'etl_uber_data', 'transform', 'manual__2023-07-10T02:44:19.817965+00:00', '--job-id', '41', '--raw', '--subdir', 'DAGS_FOLDER/etl_uber_data.py', '--cfg-path', '/tmp/tmpzjr4gu60']
[2023-07-10T03:58:58.660+0000] {standard_task_runner.py:85} INFO - Job 41: Subtask transform
[2023-07-10T03:58:58.701+0000] {task_command.py:410} INFO - Running <TaskInstance: etl_uber_data.transform manual__2023-07-10T02:44:19.817965+00:00 [running]> on host 1481ab9bb806
[2023-07-10T03:58:58.787+0000] {taskinstance.py:1547} INFO - Exporting env vars: AIRFLOW_CTX_DAG_OWNER='Mervyn Frost' AIRFLOW_CTX_DAG_ID='etl_uber_data' AIRFLOW_CTX_TASK_ID='transform' AIRFLOW_CTX_EXECUTION_DATE='2023-07-10T02:44:19.817965+00:00' AIRFLOW_CTX_TRY_NUMBER='9' AIRFLOW_CTX_DAG_RUN_ID='manual__2023-07-10T02:44:19.817965+00:00'
[2023-07-10T03:58:59.263+0000] {taskinstance.py:1824} ERROR - Task failed with exception
Traceback (most recent call last):
  File "/home/airflow/.local/lib/python3.7/site-packages/airflow/operators/python.py", line 181, in execute
    return_value = self.execute_callable()
  File "/home/airflow/.local/lib/python3.7/site-packages/airflow/operators/python.py", line 198, in execute_callable
    return self.python_callable(*self.op_args, **self.op_kwargs)
  File "/opt/airflow/dags/etl_uber_data.py", line 108, in transform
    return {datetime_dim, passenger_count_dim, trip_distance_dim, rate_code_dim, pickup_location_dim, dropoff_location_dim, payment_type_dim, fact_table}
TypeError: unhashable type: 'DataFrame'
[2023-07-10T03:58:59.274+0000] {taskinstance.py:1350} INFO - Marking task as UP_FOR_RETRY. dag_id=etl_uber_data, task_id=transform, execution_date=20230710T024419, start_date=20230710T035858, end_date=20230710T035859
[2023-07-10T03:58:59.284+0000] {standard_task_runner.py:109} ERROR - Failed to execute job 41 for task transform (unhashable type: 'DataFrame'; 4919)
[2023-07-10T03:58:59.312+0000] {local_task_job_runner.py:225} INFO - Task exited with return code 1
[2023-07-10T03:58:59.326+0000] {taskinstance.py:2653} INFO - 0 downstream tasks scheduled from follow-on schedule check
