[2023-07-10T02:59:27.877+0000] {taskinstance.py:1103} INFO - Dependencies all met for dep_context=non-requeueable deps ti=<TaskInstance: etl_uber_data.transform manual__2023-07-10T02:44:19.817965+00:00 [queued]>
[2023-07-10T02:59:27.884+0000] {taskinstance.py:1103} INFO - Dependencies all met for dep_context=requeueable deps ti=<TaskInstance: etl_uber_data.transform manual__2023-07-10T02:44:19.817965+00:00 [queued]>
[2023-07-10T02:59:27.885+0000] {taskinstance.py:1308} INFO - Starting attempt 3 of 4
[2023-07-10T02:59:27.896+0000] {taskinstance.py:1327} INFO - Executing <Task(PythonOperator): transform> on 2023-07-10 02:44:19.817965+00:00
[2023-07-10T02:59:27.900+0000] {standard_task_runner.py:57} INFO - Started process 1736 to run task
[2023-07-10T02:59:27.903+0000] {standard_task_runner.py:84} INFO - Running: ['***', 'tasks', 'run', 'etl_uber_data', 'transform', 'manual__2023-07-10T02:44:19.817965+00:00', '--job-id', '21', '--raw', '--subdir', 'DAGS_FOLDER/etl_uber_data.py', '--cfg-path', '/tmp/tmpzq6t403q']
[2023-07-10T02:59:27.904+0000] {standard_task_runner.py:85} INFO - Job 21: Subtask transform
[2023-07-10T02:59:27.942+0000] {task_command.py:410} INFO - Running <TaskInstance: etl_uber_data.transform manual__2023-07-10T02:44:19.817965+00:00 [running]> on host 1481ab9bb806
[2023-07-10T02:59:28.003+0000] {taskinstance.py:1547} INFO - Exporting env vars: AIRFLOW_CTX_DAG_OWNER='Mervyn Frost' AIRFLOW_CTX_DAG_ID='etl_uber_data' AIRFLOW_CTX_TASK_ID='transform' AIRFLOW_CTX_EXECUTION_DATE='2023-07-10T02:44:19.817965+00:00' AIRFLOW_CTX_TRY_NUMBER='3' AIRFLOW_CTX_DAG_RUN_ID='manual__2023-07-10T02:44:19.817965+00:00'
[2023-07-10T02:59:28.004+0000] {taskinstance.py:1824} ERROR - Task failed with exception
Traceback (most recent call last):
  File "/home/airflow/.local/lib/python3.7/site-packages/airflow/operators/python.py", line 181, in execute
    return_value = self.execute_callable()
  File "/home/airflow/.local/lib/python3.7/site-packages/airflow/operators/python.py", line 198, in execute_callable
    return self.python_callable(*self.op_args, **self.op_kwargs)
TypeError: transform() missing 1 required positional argument: 'dataframe'
[2023-07-10T02:59:28.011+0000] {taskinstance.py:1350} INFO - Marking task as UP_FOR_RETRY. dag_id=etl_uber_data, task_id=transform, execution_date=20230710T024419, start_date=20230710T025927, end_date=20230710T025928
[2023-07-10T02:59:28.020+0000] {standard_task_runner.py:109} ERROR - Failed to execute job 21 for task transform (transform() missing 1 required positional argument: 'dataframe'; 1736)
[2023-07-10T02:59:28.035+0000] {local_task_job_runner.py:225} INFO - Task exited with return code 1
[2023-07-10T02:59:28.048+0000] {taskinstance.py:2653} INFO - 0 downstream tasks scheduled from follow-on schedule check
