[2023-07-10T08:50:33.877+0000] {taskinstance.py:1103} INFO - Dependencies all met for dep_context=non-requeueable deps ti=<TaskInstance: etl_uber_data.extract manual__2023-07-10T02:44:19.817965+00:00 [queued]>
[2023-07-10T08:50:33.887+0000] {taskinstance.py:1103} INFO - Dependencies all met for dep_context=requeueable deps ti=<TaskInstance: etl_uber_data.extract manual__2023-07-10T02:44:19.817965+00:00 [queued]>
[2023-07-10T08:50:33.887+0000] {taskinstance.py:1308} INFO - Starting attempt 35 of 36
[2023-07-10T08:50:33.899+0000] {taskinstance.py:1327} INFO - Executing <Task(PythonOperator): extract> on 2023-07-10 02:44:19.817965+00:00
[2023-07-10T08:50:33.904+0000] {standard_task_runner.py:57} INFO - Started process 26178 to run task
[2023-07-10T08:50:33.907+0000] {standard_task_runner.py:84} INFO - Running: ['***', 'tasks', 'run', 'etl_uber_data', 'extract', 'manual__2023-07-10T02:44:19.817965+00:00', '--job-id', '299', '--raw', '--subdir', 'DAGS_FOLDER/etl_uber_data.py', '--cfg-path', '/tmp/tmpllv31q7b']
[2023-07-10T08:50:33.909+0000] {standard_task_runner.py:85} INFO - Job 299: Subtask extract
[2023-07-10T08:50:33.950+0000] {task_command.py:410} INFO - Running <TaskInstance: etl_uber_data.extract manual__2023-07-10T02:44:19.817965+00:00 [running]> on host 1481ab9bb806
[2023-07-10T08:50:34.025+0000] {taskinstance.py:1547} INFO - Exporting env vars: AIRFLOW_CTX_DAG_OWNER='Mervyn Frost' AIRFLOW_CTX_DAG_ID='etl_uber_data' AIRFLOW_CTX_TASK_ID='extract' AIRFLOW_CTX_EXECUTION_DATE='2023-07-10T02:44:19.817965+00:00' AIRFLOW_CTX_TRY_NUMBER='35' AIRFLOW_CTX_DAG_RUN_ID='manual__2023-07-10T02:44:19.817965+00:00'
[2023-07-10T08:50:34.220+0000] {taskinstance.py:1824} ERROR - Task failed with exception
Traceback (most recent call last):
  File "/home/airflow/.local/lib/python3.7/site-packages/airflow/operators/python.py", line 181, in execute
    return_value = self.execute_callable()
  File "/home/airflow/.local/lib/python3.7/site-packages/airflow/operators/python.py", line 198, in execute_callable
    return self.python_callable(*self.op_args, **self.op_kwargs)
  File "/opt/airflow/dags/etl_uber_data.py", line 24, in extract
    ti.xcom_push(key='dataframe', value=df)
NameError: name 'ti' is not defined
[2023-07-10T08:50:34.232+0000] {taskinstance.py:1350} INFO - Marking task as UP_FOR_RETRY. dag_id=etl_uber_data, task_id=extract, execution_date=20230710T024419, start_date=20230710T085033, end_date=20230710T085034
[2023-07-10T08:50:34.243+0000] {standard_task_runner.py:109} ERROR - Failed to execute job 299 for task extract (name 'ti' is not defined; 26178)
[2023-07-10T08:50:34.281+0000] {local_task_job_runner.py:225} INFO - Task exited with return code 1
[2023-07-10T08:50:34.302+0000] {taskinstance.py:2653} INFO - 0 downstream tasks scheduled from follow-on schedule check
